<?xml version='1.0' encoding='utf-8'?>
<!-- Robot body structure only - assets and compiler defined in parent file -->
<mujoco>
  <option integrator="implicitfast" cone="elliptic" impratio="10"/>

  <default>
    <default class="piper">
      <joint frictionloss="1" armature="0.01" damping="2000"/>
      <position inheritrange="1" forcerange="-100 100"/>
      <default class="finger">
        <joint frictionloss="1" type="slide" damping="1000"/>
        <position forcerange="-10 10"/>
      </default>
      <default class="visual">
        <geom group="2" type="mesh" contype="0" conaffinity="0" density="0"/>
      </default>
      <default class="collision">
        <geom group="3" type="capsule"/>
      </default>
    </default>
  </default>

  <worldbody>
    <light name="spotlight" mode="targetbodycom" target="link8" pos="0 0 1"/>
    <body name="base_link" childclass="piper" gravcomp="1">
      <inertial pos="-0.00979275 1.82906e-06 0.04101" quat="0.692988 -0.137524 -0.137826 0.69416" mass="0.162549"
        diaginertia="0.000269445 0.000227478 0.000221437"/>
      <geom class="visual" density="0" mesh="base_link" material="gray_mat"/>
      <geom class="collision" mesh="base_link"/>
      <body name="link1" pos="0 0 0.123" quat="0.707105 0 0 -0.707108" gravcomp="1">
        <inertial pos="0.00131676 0.000310289 -0.00922875" quat="0.557105 0.432155 0.377373 0.600388" mass="0.097868"
          diaginertia="9.25942e-05 8.3083e-05 7.69469e-05"/>
        <joint name="joint1" axis="0 0 1" range="-2.618 2.618"/>
        <geom class="visual" density="0" mesh="link1" material="gray_mat"/>
        <geom class="collision" mesh="link1"/>
        <body name="link2" quat="0.499998 0.5 -0.500002 -0.5" gravcomp="1">
          <inertial pos="0.148794 -0.00242027 0.00175155" quat="-0.0249063 0.70684 0.00803509 0.706889" mass="0.290889"
            diaginertia="0.00177549 0.00173142 0.00014552"/>
          <joint name="joint2" axis="0 0 1" range="0 3.14"/>
          <geom mesh="link2_0" material="gray_mat" class="visual"/>
          <geom mesh="link2_1" material="darker_gray_mat" class="visual"/>
          <geom mesh="link2_2" material="darker_gray_mat" class="visual"/>
          <geom mesh="link2_3" material="dark_gray_mat" class="visual"/>
          <geom mesh="link2_4" material="dark_gray_mat" class="visual"/>
          <geom mesh="link2_5" material="red_mat" class="visual"/>
          <geom mesh="link2_6" material="dark_gray_mat" class="visual"/>
          <geom mesh="link2_7" material="gray_mat" class="visual"/>
          <geom mesh="link2_8" material="red_mat" class="visual"/>
          <geom mesh="link2_9" material="red_mat" class="visual"/>
          <geom mesh="link2_10" material="gray_mat" class="visual"/>
          <geom mesh="link2_11" material="red_mat" class="visual"/>
          <geom mesh="link2_12" material="red_mat" class="visual"/>
          <geom mesh="link2_13" material="red_mat" class="visual"/>
          <geom mesh="link2_14" material="red_mat" class="visual"/>
          <geom mesh="link2_15" material="red_mat" class="visual"/>
          <geom mesh="link2_16" material="red_mat" class="visual"/>
          <geom mesh="link2_17" material="red_mat" class="visual"/>
          <geom mesh="link2_18" material="red_mat" class="visual"/>
          <geom mesh="link2_19" material="red_mat" class="visual"/>
          <geom mesh="link2_20" material="red_mat" class="visual"/>
          <geom mesh="link2_21" material="gray_mat" class="visual"/>
          <geom mesh="link2_22" material="red_mat" class="visual"/>
          <geom mesh="link2_23" material="red_mat" class="visual"/>
          <geom mesh="link2_24" material="red_mat" class="visual"/>
          <geom mesh="link2_25" material="dark_gray_mat" class="visual"/>
          <geom mesh="link2_26" material="red_mat" class="visual"/>
          <geom mesh="link2_27" material="darker_gray_mat" class="visual"/>
          <geom mesh="link2_28" material="darker_gray_mat" class="visual"/>
          <geom mesh="link2_29" material="darker_gray_mat" class="visual"/>
          <geom mesh="link2_30" material="darker_gray_mat" class="visual"/>
          <geom mesh="link2_31" material="light_medium_gray_mat" class="visual"/>
          <geom mesh="link2" class="collision"/>
          <body name="link3" pos="0.28358 0.028726 0" quat="0.998726 0 0 0.0504536" gravcomp="1">
            <inertial pos="-0.0996835 0.0349477 0.000508026" quat="0.0777021 0.702287 -0.0990541 0.700674"
              mass="0.290848" diaginertia="0.000241946 0.000222224 0.000100384"/>
            <joint name="joint3" pos="0 0 0" axis="0 0 1" range="-2.697 0"/>
            <geom mesh="link3_0" material="darker_gray_mat" class="visual"/>
            <geom mesh="link3_1" material="red_mat" class="visual"/>
            <geom mesh="link3_2" material="gray_mat" class="visual"/>
            <geom mesh="link3_3" material="gray_mat" class="visual"/>
            <geom mesh="link3_4" material="gray_mat" class="visual"/>
            <geom mesh="link3_5" material="gray_mat" class="visual"/>
            <geom mesh="link3_7" material="darker_gray_mat" class="visual"/>
            <geom mesh="link3_8" material="white_mat" class="visual"/>
            <geom mesh="link3_9" material="red_mat" class="visual"/>
            <geom mesh="link3_10" material="white_mat" class="visual"/>
            <geom mesh="link3_11" material="white_mat" class="visual"/>
            <geom mesh="link3_12" material="white_mat" class="visual"/>
            <geom mesh="link3_13" material="white_mat" class="visual"/>
            <geom mesh="link3_14" material="gray_mat" class="visual"/>
            <geom mesh="link3_15" material="gray_mat" class="visual"/>
            <geom mesh="link3_16" material="gray_mat" class="visual"/>
            <geom mesh="link3_17" material="gray_mat" class="visual"/>
            <geom mesh="link3_18" material="gray_mat" class="visual"/>
            <geom mesh="link3_19" material="gray_mat" class="visual"/>
            <geom mesh="link3_20" material="gray_mat" class="visual"/>
            <geom mesh="link3_21" material="gray_mat" class="visual"/>
            <geom mesh="link3_22" material="gray_mat" class="visual"/>
            <geom mesh="link3_23" material="gray_mat" class="visual"/>
            <geom mesh="link3_24" material="gray_mat" class="visual"/>
            <geom mesh="link3_25" material="gray_mat" class="visual"/>
            <geom mesh="link3_26" material="gray_mat" class="visual"/>
            <geom mesh="link3_27" material="gray_mat" class="visual"/>
            <geom mesh="link3_28" material="gray_mat" class="visual"/>
            <geom mesh="link3" class="collision"/>
            <body name="link4" pos="-0.24221 0.068514 0" quat="0.544767 -0.544769 -0.450809 0.450808" gravcomp="1">
              <inertial pos="0.000276465 -0.00102804 -0.00472831" quat="0.492305 0.505285 0.503294 0.499017"
                mass="0.127087" diaginertia="4.87057e-05 4.10595e-05 3.82001e-05"/>
              <joint name="joint4" axis="0 0 1" range="-1.832 1.832"/>
              <geom mesh="link4_2" material="gray_mat" class="visual"/>
              <geom mesh="link4_3" material="darker_gray_mat" class="visual"/>
              <geom mesh="link4_4" material="gray_mat" class="visual"/>
              <geom mesh="link4_5" material="gray_mat" class="visual"/>
              <geom mesh="link4_6" material="gray_mat" class="visual"/>
              <geom mesh="link4" class="collision"/>
              <body name="link5" quat="0.707105 0.707108 0 0" gravcomp="1">
                <inertial pos="8.82262e-05 0.0566829 -0.0019612" quat="0.507447 0.490986 0.506887 0.494466"
                  mass="0.144711" diaginertia="0.001 0.001 0.001"/>
                <joint name="joint5" axis="0 0 1" range="-1.22 1.22"/>
                <geom mesh="link5_2" material="black_mat" class="visual"/>
                <geom mesh="link5_3" material="black_mat" class="visual"/>
                <geom mesh="link5_4" material="darker_gray_mat" class="visual"/>
                <geom mesh="link5_5" material="gray_mat" class="visual"/>
                <geom mesh="link5_6" material="light_gray_mat" class="visual"/>
                <geom mesh="link5_7" material="gray_mat" class="visual"/>
                <geom mesh="link5_8" material="gray_mat" class="visual"/>
                <geom mesh="link5" class="collision"/>
                <body name="link6" pos="0 0.091 0.0014165" quat="0 0 -0.707105 -0.707108" gravcomp="1">
                  <inertial pos="0.0010312 0.0121761 0.0315481" quat="0.0230402 0.707091 0.0373344 0.70576" mass="1.2"
                    diaginertia="0.001 0.001 0.001"/>
                  <joint name="joint6" axis="0 0 1" range="-3.14 3.14"/>
                  <geom quat="0.707105 0 0 0.707108" mesh="link6" material="gray_mat" class="visual"/>
                  <geom quat="0.707105 0 0 0.707108" mesh="link6" class="collision"/>
                  <body name="link7" pos="0 0 0.13503" quat="1.89468e-08 1.89469e-08 0.707108 0.707105" gravcomp="1">
                    <inertial pos="-0.000277778 -0.0467673 -0.00921029" quat="0.46134 0.536174 -0.553273 0.439968"
                      mass="0.0264823" diaginertia="0.001 0.001 0.001"/>
                    <joint name="joint7" axis="0 0 -1" class="finger" range="0 0.035"/>
                    <geom mesh="link7" material="gray_mat" class="visual"/>
                    <!-- Main gripper finger pad with high friction -->
                    <geom type="box" size=".010 .035 .003" pos="0 -0.03 0" contype="1" conaffinity="1" condim="4"
                          friction="3.0 0.5 0.05" solref="0.002 1" solimp="0.95 0.99 0.001"/>
                  </body>
                  <body name="link8" pos="0 0 0.13503" quat="1.89468e-08 -1.89469e-08 -0.707108 0.707105" gravcomp="1">
                    <inertial pos="0.000277817 0.0467674 -0.0092103" quat="0.553273 0.439968 -0.46134 0.536174"
                      mass="0.0264822" diaginertia="0.001 0.001 0.001"/>
                    <joint name="joint8" axis="0 0 1" class="finger" range="-0.035 0"/>
                    <geom mesh="link8" material="gray_mat" class="visual"/>
                    <!-- Main gripper finger pad with high friction -->
                    <geom type="box" size=".010 .035 .003" pos="0 0.03 0" contype="1" conaffinity="1" condim="4"
                          friction="3.0 0.5 0.05" solref="0.002 1" solimp="0.95 0.99 0.001"/>
                  </body>
                </body>
              </body>
            </body>
          </body>
        </body>
      </body>
    </body>
  </worldbody>

  <contact>
    <exclude body1="base_link" body2="link1"/>
  </contact>

  <actuator>
    <position name="joint1" joint="joint1" class="piper" kp="60" kv="8"/>
    <position name="joint2" joint="joint2" class="piper" kp="60" kv="8"/>
    <position name="joint3" joint="joint3" class="piper" kp="60" kv="8"/>
    <position name="joint4" joint="joint4" class="piper" kp="30" kv="6"/>
    <position name="joint5" joint="joint5" class="piper" kp="8" kv="2"/>
    <position name="joint6" joint="joint6" class="piper" kp="8" kv="2"/>
    <position name="joint7" joint="joint7" class="finger" kp="200" kv="20" forcerange="-100 100"/>
    <position name="joint8" joint="joint8" class="finger" kp="200" kv="20" forcerange="-100 100"/>
  </actuator>

  <!-- Keyframe removed - incompatible with scenes that have free-floating objects -->
</mujoco>
