<?xml version="1.0" encoding="utf-8"?>
<robot name="piper_gripper">
  <link name="gripper_base">
    <inertial>
      <origin xyz="-0.000183807162235591 8.05033155577911E-05 0.0321436689908876" rpy="0 0 0" />
      <mass value="0.45" />
      <inertia ixx="0.00092934" ixy="0.00000034" ixz="-0.00000738" iyy="0.00071447" iyz="0.00000005" izz="0.00039442" />
    </inertial>
    <visual>
      <origin xyz="0 0 0" rpy="0 0 0" />
      <geometry>
        <mesh filename="package://agilex_piper_urdf/meshes/gripper_base.STL" />
      </geometry>
      <material name="">
        <color rgba="0.792156862745098 0.819607843137255 0.933333333333333 1" />
      </material>
    </visual>
    <collision>
      <origin xyz="0 0 0" rpy="0 0 0" />
      <geometry>
        <mesh filename="package://agilex_piper_urdf/meshes/gripper_base.STL" />
      </geometry>
    </collision>
  </link>

  <link name="link7">
    <inertial>
      <origin xyz="0.00065123185041968 -0.0491929869131989 0.00972258769184025" rpy="0 0 0" />
      <mass value="0.025" />
      <inertia ixx="0.00007371" ixy="-0.00000113" ixz="0.00000021" iyy="-0.00000113" iyz="-0.00001372" izz="0.0000747" />
    </inertial>
    <visual>
      <origin xyz="0 0 0" rpy="0 0 0" />
      <geometry>
        <mesh filename="package://agilex_piper_urdf/meshes/link7.STL" />
      </geometry>
      <material name="">
        <color rgba="0.792156862745098 0.819607843137255 0.933333333333333 1" />
      </material>
    </visual>
    <collision>
      <origin xyz="0 0 0" rpy="0 0 0" />
      <geometry>
        <mesh filename="package://agilex_piper_urdf/meshes/link7.STL" />
      </geometry>
    </collision>
  </link>

  <joint name="joint7" type="prismatic">
    <origin xyz="0 0 0.1358" rpy="1.5708 0 0" />
    <parent link="gripper_base" />
    <child link="link7" />
    <axis xyz="0 0 1" />
    <limit lower="0" upper="0.035" effort="10" velocity="1" />
  </joint>

  <link name="link8">
    <inertial>
      <origin xyz="0.000651231850419722 -0.0491929869131991 0.00972258769184024" rpy="0 0 0" />
      <mass value="0.025" />
      <inertia ixx="0.00007371" ixy="-0.00000113" ixz="0.00000021" iyy="-0.00000113" iyz="-0.00001372" izz="0.0000747" />
    </inertial>
    <visual>
      <origin xyz="0 0 0" rpy="0 0 0" />
      <geometry>
        <mesh filename="package://agilex_piper_urdf/meshes/link8.STL" />
      </geometry>
      <material name="">
        <color rgba="0.792156862745098 0.819607843137255 0.933333333333333 1" />
      </material>
    </visual>
    <collision>
      <origin xyz="0 0 0" rpy="0 0 0" />
      <geometry>
        <mesh filename="package://agilex_piper_urdf/meshes/link8.STL" />
      </geometry>
    </collision>
  </link>

  <joint name="joint8" type="prismatic">
    <origin xyz="0 0 0.1358" rpy="1.5708 0 -3.1416" />
    <parent link="gripper_base" />
    <child link="link8" />
    <axis xyz="0 0 -1" />
    <limit lower="-0.035" upper="0" effort="10" velocity="1" />
  </joint>

  <link name="tcp">
    <inertial>
      <origin xyz="0 0 0" rpy="0 0 0" />
      <mass value="0.001" />
      <inertia ixx="0.000001" ixy="0" ixz="0" iyy="0.000001" iyz="0" izz="0.000001" />
    </inertial>
  </link>

  <joint name="tcp_joint" type="fixed">
    <origin xyz="0 0 0.1000" rpy="0 0 0" />
    <parent link="gripper_base" />
    <child link="tcp" />
  </joint>
</robot>
